Workbook

Sheet Index
B1: DCF Valuation
B2: Sheet index
B4: # | C4: Worksheet
B5: 1 | C5: 1.Input -->
B6: =B5+1 -> 2 | C6: P&L assumptions
B7: =B6+1 -> 3 | C7: BS assumptions
B8: =B7+1 -> 4 | C8: 2.Output -->
B9: =B8+1 -> 5 | C9: P&L
B10: =B9+1 -> 6 | C10: BS
B11: =B10+1 -> 7 | C11: Cash Flow
B12: =B11+1 -> 8 | C12: DCF valuation

Sheet P&L Source
B1: P&L source
B3: USD in thousands | D3: 2018 Act | E3: 2019 Act | F3: 2020 Act
B4: Revenue from sales and services | D4: 177203 | E4: 188618 | F4: 208366
B5: Other revenue | D5: 3520 | E5: 2416 | F5: 2585
B6: Revenue | D6: =D4+D5 -> 180723 | E6: =E4+E5 -> 191034 | F6: =F4+F5 -> 210951
B8: Raw materials | D8: -139903.04 | E8: -138922.99 | F8: -150080.47
B9: Direct costs | D9: -2491.328 | E9: -11649.178 | F9: -7442.6496
B10: Cost for services | D10: -16389.594 | E10: -17878.31 | F10: -22293.312
B11: Lease costs | D11: -290.7264 | E11: -246.1312 | F11: -120.9216
B12: Other operating expenses | D12: -1330.9952 | E12: -1123.456 | F12: -1452.7744
B14: EBITDA | D14: =D6+SUM(D8:D12) -> 20317.317 | E14: =E6+SUM(E8:E12) -> 21213.936 | F14: =F6+SUM(F8:F12) -> 29560.874
B16: D&A | D16: -2907.8 | E16: -4649.8 | F16: -6430.66
B18: EBIT | D18: =D14+D16 -> 17409.517 | E18: =E14+E16 -> 16564.136 | F18: =F14+F16 -> 23130.214
B20: Financial income/expenses | D20: -1266.3 | E20: -2190.9 | F20: -2663.92
B21: Extraordinary income | D21: -317.58 | E21: -864.3 | F21: -320.26
B23: EBT | D23: =D18+D21+D20 -> 15825.637 | E23: =E18+E21+E20 -> 13508.936 | F23: =F18+F21+F20 -> 20146.034
B25: Taxes | D25: -3805.776 | E25: -3050.192 | F25: -3814.88
B27: Net Income | D27: =D23+D25 -> 12019.861 | E27: =E23+E25 -> 10458.744 | F27: =F23+F25 -> 16331.154

Sheet BS source
B1: BS source
B3: USD in thousands | D3: 31Dec18 Act | E3: 31Dec19 Act | F3: 31Dec20 Act | H3: USD in thousands | J3: 31Dec18 Act | K3: 31Dec19 Act | L3: 31Dec20 Act
B4: Intangible assets | D4: 5961.6 | E4: 5840 | F4: 5650 | H4: Share Capital | J4: 6784.8 | K4: 6800 | L4: 7508
B5: PP&E | D5: 45106.4 | E5: 49072.4 | F5: 56109.2 | H5: Reserves | J5: 46224 | K5: 44414.4 | L5: 46513.2
B6: Financial assets | D6: 8824 | E6: 9831 | F6: 10323 | H6: Retained earnings | J6: 16393.7 | K6: 25993.7 | L6: 21516
H7: Profit/(loss) for the year | J7: 12019.861 | K7: 10458.744 | L7: 16331.154
B8: Fixed assets | D8: =D6+D5+D4 -> 59892 | E8: =E6+E5+E4 -> 64743.4 | F8: =F6+F5+F4 -> 72082.2 | H8: Total Equity | J8: =SUM(J4:J7) -> 81422.361 | K8: =SUM(K4:K7) -> 87666.844 | L8: =SUM(L4:L7) -> 91868.354
B10: Inventory | D10: 31167.2 | E10: 36396.8 | F10: 46212 | H10: Trade payable | J10: 15891.2 | K10: 26351.6 | L10: 36189.6
B11: Trade receivables | D11: 32883.6 | E11: 38556 | F11: 43581.6 | H11: Other liabilities | J11: 5315 | K11: 4334 | L11: 6473.0464
B12: Other assets | D12: 8841.6 | E12: 11359.2 | F12: 17602.8 | H12: Deferred taxes | J12: 478.83867 | K12: 1217.956 | L12: 1760.4
H13: Provisions for retirement benefits | J13: 175.2 | K13: 248.4 | L13: 240
B14: Cash and equivalents | D14: 11791.2 | E14: 19408.8 | F14: 8173.6
B15: Non fixed assets | D15: =+D14+D12+D11+D10 -> 84683.6 | E15: =+E14+E12+E11+E10 -> 105720.8 | F15: =+F14+F12+F11+F10 -> 115570 | H15: Bank borrowings | J15: 37402.6 | K15: 45594.6 | L15: 50680.4
H16: Other Financial liabilities | J16: 3890.4 | K16: 5050.8 | L16: 440.4
H17: Total Liabilities | J17: =J16+J15+SUM(J10:J13) -> 63153.239 | K17: =K16+K15+SUM(K10:K13) -> 82797.356 | L17: =L16+L15+SUM(L10:L13) -> 95783.846
B19: Total Assets | D19: =D15+D8 -> 144575.6 | E19: =E15+E8 -> 170464.2 | F19: =F15+F8 -> 187652.2 | H19: Total Liabilities & Equity | J19: =J17+J8 -> 144575.6 | K19: =K17+K8 -> 170464.2 | L19: =L17+L8 -> 187652.2

Sheet P&L assumptions
A1: P&L assumptions
G2: Scenarios:
G3: Case 1: | H3: Optimistic case
G4: Case 2: | H4: Base case
A5: Selected case | C5: 1 | G5: Case 3: | H5: Worst case
A8: $ in thousands | C8: FY18 Actual | D8: FY19 Actual | E8: FY20 Actual | G8: FY21 Forecast | H8: FY22 Forecast | I8: FY23 Forecast | J8: FY24 Forecast | K8: FY25 Forecast
A9: Revenues | C9: ='P&L Source'!D4 -> 177203 | D9: ='P&L Source'!E4 -> 188618 | E9: ='P&L Source'!F4 -> 208366 | G9: =E9*(1+G10) -> 229202.6 | H9: =G9*(1+H10) -> 252122.86 | I9: =H9*(1+I10) -> 277335.15 | J9: =I9*(1+J10) -> 305068.66 | K9: =J9*(1+K10) -> 335575.53
A10: y-o-y growth% | D10: =D9/C9-1 -> 0.064417645 | E10: =E9/D9-1 -> 0.10469839 | G10: =CHOOSE($C$5,G11,G12,G13) -> 0.1 | H10: =CHOOSE($C$5,H11,H12,H13) -> 0.1 | I10: =CHOOSE($C$5,I11,I12,I13) -> 0.1 | J10: =CHOOSE($C$5,J11,J12,J13) -> 0.1 | K10: =CHOOSE($C$5,K11,K12,K13) -> 0.1
A11: Case 1: | G11: 0.1 | H11: 0.1 | I11: 0.1 | J11: 0.1 | K11: 0.1
A12: Case 2: | G12: 0.08 | H12: 0.08 | I12: 0.08 | J12: 0.08 | K12: 0.08
A13: Case 3: | G13: 0.06 | H13: 0.06 | I13: 0.06 | J13: 0.06 | K13: 0.06
A15: Other revenues | C15: ='P&L Source'!D5 -> 3520 | D15: ='P&L Source'!E5 -> 2416 | E15: ='P&L Source'!F5 -> 2585 | G15: =E15*(1+G17) -> 2585 | H15: =G15*(1+H16) -> 2585 | I15: =H15*(1+I16) -> 2585 | J15: =I15*(1+J16) -> 2585 | K15: =J15*(1+K16) -> 2585
A16: y-o-y growth % | G16: =CHOOSE($C$5,G17,G18,G19) -> 0 | H16: =CHOOSE($C$5,H17,H18,H19) -> 0 | I16: =CHOOSE($C$5,I17,I18,I19) -> 0 | J16: =CHOOSE($C$5,J17,J18,J19) -> 0 | K16: =CHOOSE($C$5,K17,K18,K19) -> 0
A17: Case 1 | G17: 0 | H17: 0 | I17: 0 | J17: 0 | K17: 0
A18: Case 2 | G18: 0 | H18: 0 | I18: 0 | J18: 0 | K18: 0
A19: Case 3 | G19: 0 | H19: 0 | I19: 0 | J19: 0 | K19: 0
A21: Cost of goods sold | C21: ='P&L Source'!D8+'P&L Source'!D9 -> -142394.37 | D21: ='P&L Source'!E8+'P&L Source'!E9 -> -150572.17 | E21: ='P&L Source'!F8+'P&L Source'!F9 -> -157523.12 | G21: =G9*G22 -> -174193.98 | H21: =H9*H22 -> -191613.37 | I21: =I9*I22 -> -210774.71 | J21: =J9*J22 -> -231852.18 | K21: =K9*K22 -> -255037.4
A22: % of revenues | C22: =C21/C$9 -> -0.80356635 | D22: =D21/D$9 -> -0.79829161 | E22: =E21/E$9 -> -0.75599243 | G22: =CHOOSE($C$5,G23,G24,G25) -> -0.76 | H22: =CHOOSE($C$5,H23,H24,H25) -> -0.76 | I22: =CHOOSE($C$5,I23,I24,I25) -> -0.76 | J22: =CHOOSE($C$5,J23,J24,J25) -> -0.76 | K22: =CHOOSE($C$5,K23,K24,K25) -> -0.76
A23: Case 1 | G23: -0.76 | H23: -0.76 | I23: -0.76 | J23: -0.76 | K23: -0.76
A24: Case 2 | G24: -0.78 | H24: -0.78 | I24: -0.78 | J24: -0.78 | K24: -0.78
A25: Case 3 | G25: -0.8 | H25: -0.8 | I25: -0.8 | J25: -0.8 | K25: -0.8
A27: Operating expenses | C27: ='P&L Source'!D10+'P&L Source'!D11+'P&L Source'!D12 -> -18011.315 | D27: ='P&L Source'!E10+'P&L Source'!E11+'P&L Source'!E12 -> -19247.898 | E27: ='P&L Source'!F10+'P&L Source'!F11+'P&L Source'!F12 -> -23867.008 | G27: =G$9*G28 -> -22920.26 | H27: =H$9*H28 -> -25212.286 | I27: =I$9*I28 -> -27733.515 | J27: =J$9*J28 -> -30506.866 | K27: =K$9*K28 -> -33557.553
A28: % of revenues | C28: =C27/C$9 -> -0.10164227 | D28: =D27/D$9 -> -0.10204698 | E28: =E27/E$9 -> -0.11454368 | G28: =CHOOSE($C$5,G29,G30,G31) -> -0.1 | H28: =CHOOSE($C$5,H29,H30,H31) -> -0.1 | I28: =CHOOSE($C$5,I29,I30,I31) -> -0.1 | J28: =CHOOSE($C$5,J29,J30,J31) -> -0.1 | K28: =CHOOSE($C$5,K29,K30,K31) -> -0.1
A29: Case 1 | G29: -0.1 | H29: -0.1 | I29: -0.1 | J29: -0.1 | K29: -0.1
A30: Case 2 | G30: -0.105 | H30: -0.105 | I30: -0.105 | J30: -0.105 | K30: -0.105
A31: Case 3 | G31: -0.11 | H31: -0.11 | I31: -0.11 | J31: -0.11 | K31: -0.11
A33: D&A | C33: ='P&L Source'!D16 -> -2907.8 | D33: ='P&L Source'!E16 -> -4649.8 | E33: ='P&L Source'!F16 -> -6430.66 | G33: =G$9*G34 -> -4584.052 | H33: =H$9*H34 -> -5042.4572 | I33: =I$9*I34 -> -5546.7029 | J33: =J$9*J34 -> -6101.3732 | K33: =K$9*K34 -> -6711.5105
A34: % of revenues | C34: =C33/C$9 -> -0.016409429 | D34: =D33/D$9 -> -0.024651942 | E34: =E33/E$9 -> -0.030862329 | G34: =CHOOSE($C$5,G35,G36,G37) -> -0.02 | H34: =CHOOSE($C$5,H35,H36,H37) -> -0.02 | I34: =CHOOSE($C$5,I35,I36,I37) -> -0.02 | J34: =CHOOSE($C$5,J35,J36,J37) -> -0.02 | K34: =CHOOSE($C$5,K35,K36,K37) -> -0.02
A35: Case 1 | G35: -0.02 | H35: -0.02 | I35: -0.02 | J35: -0.02 | K35: -0.02
A36: Case 2 | G36: -0.025 | H36: -0.025 | I36: -0.025 | J36: -0.025 | K36: -0.025
A37: Case 3 | G37: -0.03 | H37: -0.03 | I37: -0.03 | J37: -0.03 | K37: -0.03
A39: Interest expense | C39: ='P&L Source'!D20 -> -1266.3 | D39: ='P&L Source'!E20 -> -2190.9 | E39: ='P&L Source'!F20 -> -2663.92 | G39: =E39*(1+G41) -> -2663.92 | H39: =G39*(1+H40) -> -2663.92 | I39: =H39*(1+I40) -> -2663.92 | J39: =I39*(1+J40) -> -2663.92 | K39: =J39*(1+K40) -> -2663.92
A40: y-o-y growth % | G40: =CHOOSE($C$5,G41,G42,G43) -> 0 | H40: =CHOOSE($C$5,H41,H42,H43) -> 0 | I40: =CHOOSE($C$5,I41,I42,I43) -> 0 | J40: =CHOOSE($C$5,J41,J42,J43) -> 0 | K40: =CHOOSE($C$5,K41,K42,K43) -> 0
A41: Case 1 | G41: 0 | H41: 0 | I41: 0 | J41: 0 | K41: 0
A42: Case 2 | G42: 0 | H42: 0 | I42: 0 | J42: 0 | K42: 0
A43: Case 3 | G43: 0 | H43: 0 | I43: 0 | J43: 0 | K43: 0
A45: Extraordinary income | C45: ='P&L Source'!D21 -> -317.58 | D45: ='P&L Source'!E21 -> -864.3 | E45: ='P&L Source'!F21 -> -320.26 | G45: =#REF!*(1+G46) -> #REF! | H45: =G45*(1+H46) -> #REF! | I45: =H45*(1+I46) -> #REF! | J45: =I45*(1+J46) -> #REF! | K45: =J45*(1+K46) -> #REF!
A46: y-o-y growth % | D46: =D45/C45-1 -> 1.721519 | E46: =E45/D45-1 -> -0.62945736 | G46: =CHOOSE($C$5,G47,G48,G49) -> 0 | H46: =CHOOSE($C$5,H47,H48,H49) -> 0 | I46: =CHOOSE($C$5,I47,I48,I49) -> 0 | J46: =CHOOSE($C$5,J47,J48,J49) -> 0 | K46: =CHOOSE($C$5,K47,K48,K49) -> 0
A47: Case 1 | G47: 0 | H47: 0 | I47: 0 | J47: 0 | K47: 0
A48: Case 2 | G48: 0 | H48: 0 | I48: 0 | J48: 0 | K48: 0
...

Sheet BS assumptions
B1: BS assumptions
B4: $ in thousands | C4: 31Dec18 Actual | D4: 31Dec19 Actual | E4: 31Dec20 Actual | G4: 31Dec21 Forecast | H4: 31Dec22 Forecast | I4: 31Dec23 Forecast | J4: 31Dec24 Forecast | K4: 31Dec25 Forecast
B5: Trade receivable | C5: ='BS source'!D11 -> 32883.6 | D5: ='BS source'!E11 -> 38556 | E5: ='BS source'!F11 -> 43581.6 | G5: =(G6*'P&L assumptions'!G9)/365 -> 47352.305 | H5: =(H6*'P&L assumptions'!H9)/365 -> 52087.535 | I5: =(I6*'P&L assumptions'!I9)/365 -> 57296.289 | J5: =(J6*'P&L assumptions'!J9)/365 -> 63025.918 | K5: =(K6*'P&L assumptions'!K9)/365 -> 69328.509
B6: Days receivable | C6: =C5/'P&L Source'!D6*365 -> 66.413871 | D6: =D5/'P&L Source'!E6*365 -> 73.667201 | E6: =E5/'P&L Source'!F6*365 -> 75.407483 | G6: =$E$6 -> 75.407483 | H6: =$E$6 -> 75.407483 | I6: =$E$6 -> 75.407483 | J6: =$E$6 -> 75.407483 | K6: =$E$6 -> 75.407483
B8: Inventory | C8: ='BS source'!D10 -> 31167.2 | D8: ='BS source'!E10 -> 36396.8 | E8: ='BS source'!F10 -> 46212 | G8: =-(G9*'P&L assumptions'!G21)/365 -> 51102.671 | H8: =-(H9*'P&L assumptions'!H21)/365 -> 56212.938 | I8: =-(I9*'P&L assumptions'!I21)/365 -> 61834.231 | J8: =-(J9*'P&L assumptions'!J21)/365 -> 68017.654 | K8: =-(K9*'P&L assumptions'!K21)/365 -> 74819.42
B9: Days Inventory | C9: =-C8/'P&L assumptions'!C21*365 -> 79.890997 | D9: =-D8/'P&L assumptions'!D21*365 -> 88.229002 | E9: =-E8/'P&L assumptions'!E21*365 -> 107.07876 | G9: =$E$9 -> 107.07876 | H9: =$E$9 -> 107.07876 | I9: =$E$9 -> 107.07876 | J9: =$E$9 -> 107.07876 | K9: =$E$9 -> 107.07876
B11: Trade payable | C11: ='BS source'!J10 -> 15891.2 | D11: ='BS source'!K10 -> 26351.6 | E11: ='BS source'!L10 -> 36189.6 | G11: =-(G12*'P&L assumptions'!G21)/365 -> 40019.588 | H11: =-(H12*'P&L assumptions'!H21)/365 -> 44021.547 | I11: =-(I12*'P&L assumptions'!I21)/365 -> 48423.702 | J11: =-(J12*'P&L assumptions'!J21)/365 -> 53266.072 | K11: =-(K12*'P&L assumptions'!K21)/365 -> 58592.679
B12: Days payable | C12: =-C11/'P&L assumptions'!C21*365 -> 40.733971 | D12: =-D11/'P&L assumptions'!D21*365 -> 63.878566 | E12: =-E11/'P&L assumptions'!E21*365 -> 83.855653 | G12: =$E$12 -> 83.855653 | H12: =$E$12 -> 83.855653 | I12: =$E$12 -> 83.855653 | J12: =$E$12 -> 83.855653 | K12: =$E$12 -> 83.855653
B14: PP&E | C14: ='BS source'!D5 -> 45106.4 | D14: ='BS source'!E5 -> 49072.4 | E14: ='BS source'!F5 -> 56109.2 | G14: =G15*'P&L assumptions'!G9 -> 59898.019 | H14: =H15*'P&L assumptions'!H9 -> 65887.821 | I14: =I15*'P&L assumptions'!I9 -> 72476.603 | J14: =J15*'P&L assumptions'!J9 -> 79724.263 | K14: =K15*'P&L assumptions'!K9 -> 87696.689
B15: as a % of revenue | C15: =C14/'P&L assumptions'!C9 -> 0.25454648 | D15: =D14/'P&L assumptions'!D9 -> 0.26016817 | E15: =E14/'P&L assumptions'!E9 -> 0.26928194 | G15: =AVERAGE($C$15:$E$15) -> 0.2613322 | H15: =AVERAGE($C$15:$E$15) -> 0.2613322 | I15: =AVERAGE($C$15:$E$15) -> 0.2613322 | J15: =AVERAGE($C$15:$E$15) -> 0.2613322 | K15: =AVERAGE($C$15:$E$15) -> 0.2613322
B17: Other assets | C17: ='BS source'!D12 -> 8841.6 | D17: ='BS source'!E12 -> 11359.2 | E17: ='BS source'!F12 -> 17602.8 | G17: =G18*'P&L assumptions'!G9 -> 14867.518 | H17: =H18*'P&L assumptions'!H9 -> 16354.27 | I17: =I18*'P&L assumptions'!I9 -> 17989.697 | J17: =J18*'P&L assumptions'!J9 -> 19788.667 | K17: =K18*'P&L assumptions'!K9 -> 21767.534
B18: as a % of revenue | C18: =C17/'P&L assumptions'!C9 -> 0.049895318 | D18: =D17/'P&L assumptions'!D9 -> 0.060223308 | E18: =E17/'P&L assumptions'!E9 -> 0.084480194 | G18: =AVERAGE($C$18:$E$18) -> 0.064866273 | H18: =AVERAGE($C$18:$E$18) -> 0.064866273 | I18: =AVERAGE($C$18:$E$18) -> 0.064866273 | J18: =AVERAGE($C$18:$E$18) -> 0.064866273 | K18: =AVERAGE($C$18:$E$18) -> 0.064866273
B20: Other liabilities | C20: ='BS source'!J11+'BS source'!J12+'BS source'!J13 -> 5969.0387 | D20: ='BS source'!K11+'BS source'!K12+'BS source'!K13 -> 5800.356 | E20: ='BS source'!L11+'BS source'!L12+'BS source'!L13 -> 8473.4464 | G20: =G21*'P&L assumptions'!G9 -> 8029.9438 | H20: =H21*'P&L assumptions'!H9 -> 8832.9382 | I20: =I21*'P&L assumptions'!I9 -> 9716.2321 | J20: =J21*'P&L assumptions'!J9 -> 10687.855 | K20: =K21*'P&L assumptions'!K9 -> 11756.641
B21: as a % of revenue | C21: =C20/'P&L assumptions'!C9 -> 0.03368475 | D21: =D20/'P&L assumptions'!D9 -> 0.030751869 | E21: =E20/'P&L assumptions'!E9 -> 0.040666166 | G21: =AVERAGE($C$21:$E$21) -> 0.035034262 | H21: =AVERAGE($C$21:$E$21) -> 0.035034262 | I21: =AVERAGE($C$21:$E$21) -> 0.035034262 | J21: =AVERAGE($C$21:$E$21) -> 0.035034262 | K21: =AVERAGE($C$21:$E$21) -> 0.035034262

Sheet P&L 
B1: P&L
B3: $ in thousands | C3: FY18 Actual | D3: FY19 Actual | E3: FY20 Actual | G3: FY21 Forecast | H3: FY22 Forecast | I3: FY23 Forecast | J3: FY24 Forecast | K3: FY25 Forecast
B4: Revenues | C4: =SUMIF('P&L assumptions'!$A:$B,'P&L '!$B4, 'P&L assumptions'!C:C) -> 177203 | D4: =SUMIF('P&L assumptions'!$A:$B,'P&L '!$B4, 'P&L assumptions'!D:D) -> 188618 | E4: =SUMIF('P&L assumptions'!$A:$B,'P&L '!$B4, 'P&L assumptions'!E:E) -> 208366 | G4: =SUMIF('P&L assumptions'!$A:$B,'P&L '!$B4, 'P&L assumptions'!G:G) -> 229202.6 | H4: =SUMIF('P&L assumptions'!$A:$B,'P&L '!$B4, 'P&L assumptions'!H:H) -> 252122.86 | I4: =SUMIF('P&L assumptions'!$A:$B,'P&L '!$B4, 'P&L assumptions'!I:I) -> 277335.15 | J4: =SUMIF('P&L assumptions'!$A:$B,'P&L '!$B4, 'P&L assumptions'!J:J) -> 305068.66 | K4: =SUMIF('P&L assumptions'!$A:$B,'P&L '!$B4, 'P&L assumptions'!K:K) -> 335575.53
B5: Other revenues | C5: =SUMIF('P&L assumptions'!$A:$B,'P&L '!$B5, 'P&L assumptions'!C:C) -> 3520 | D5: =SUMIF('P&L assumptions'!$A:$B,'P&L '!$B5, 'P&L assumptions'!D:D) -> 2416 | E5: =SUMIF('P&L assumptions'!$A:$B,'P&L '!$B5, 'P&L assumptions'!E:E) -> 2585 | G5: =SUMIF('P&L assumptions'!$A:$B,'P&L '!$B5, 'P&L assumptions'!G:G) -> 2585 | H5: =SUMIF('P&L assumptions'!$A:$B,'P&L '!$B5, 'P&L assumptions'!H:H) -> 2585 | I5: =SUMIF('P&L assumptions'!$A:$B,'P&L '!$B5, 'P&L assumptions'!I:I) -> 2585 | J5: =SUMIF('P&L assumptions'!$A:$B,'P&L '!$B5, 'P&L assumptions'!J:J) -> 2585 | K5: =SUMIF('P&L assumptions'!$A:$B,'P&L '!$B5, 'P&L assumptions'!K:K) -> 2585
B6: Total revenues | C6: =C4+C5 -> 180723 | D6: =D4+D5 -> 191034 | E6: =E4+E5 -> 210951 | G6: =G4+G5 -> 231787.6 | H6: =H4+H5 -> 254707.86 | I6: =I4+I5 -> 279920.15 | J6: =J4+J5 -> 307653.66 | K6: =K4+K5 -> 338160.53
B7: Cost of goods sold | C7: =SUMIF('P&L assumptions'!$A:$B,'P&L '!$B7, 'P&L assumptions'!C:C) -> -142394.37 | D7: =SUMIF('P&L assumptions'!$A:$B,'P&L '!$B7, 'P&L assumptions'!D:D) -> -150572.17 | E7: =SUMIF('P&L assumptions'!$A:$B,'P&L '!$B7, 'P&L assumptions'!E:E) -> -157523.12 | G7: =SUMIF('P&L assumptions'!$A:$B,'P&L '!$B7, 'P&L assumptions'!G:G) -> -174193.98 | H7: =SUMIF('P&L assumptions'!$A:$B,'P&L '!$B7, 'P&L assumptions'!H:H) -> -191613.37 | I7: =SUMIF('P&L assumptions'!$A:$B,'P&L '!$B7, 'P&L assumptions'!I:I) -> -210774.71 | J7: =SUMIF('P&L assumptions'!$A:$B,'P&L '!$B7, 'P&L assumptions'!J:J) -> -231852.18 | K7: =SUMIF('P&L assumptions'!$A:$B,'P&L '!$B7, 'P&L assumptions'!K:K) -> -255037.4
B8: Gross margin | C8: =C7+C6 -> 38328.633 | D8: =D7+D6 -> 40461.834 | E8: =E7+E6 -> 53427.882 | G8: =G7+G6 -> 57593.624 | H8: =H7+H6 -> 63094.486 | I8: =I7+I6 -> 69145.435 | J8: =J7+J6 -> 75801.479 | K8: =K7+K6 -> 83123.126
B9: Operating expenses | C9: =SUMIF('P&L assumptions'!$A:$B,'P&L '!$B9, 'P&L assumptions'!C:C) -> -18011.315 | D9: =SUMIF('P&L assumptions'!$A:$B,'P&L '!$B9, 'P&L assumptions'!D:D) -> -19247.898 | E9: =SUMIF('P&L assumptions'!$A:$B,'P&L '!$B9, 'P&L assumptions'!E:E) -> -23867.008 | G9: =SUMIF('P&L assumptions'!$A:$B,'P&L '!$B9, 'P&L assumptions'!G:G) -> -22920.26 | H9: =SUMIF('P&L assumptions'!$A:$B,'P&L '!$B9, 'P&L assumptions'!H:H) -> -25212.286 | I9: =SUMIF('P&L assumptions'!$A:$B,'P&L '!$B9, 'P&L assumptions'!I:I) -> -27733.515 | J9: =SUMIF('P&L assumptions'!$A:$B,'P&L '!$B9, 'P&L assumptions'!J:J) -> -30506.866 | K9: =SUMIF('P&L assumptions'!$A:$B,'P&L '!$B9, 'P&L assumptions'!K:K) -> -33557.553
B10: EBITDA | C10: =C9+C8 -> 20317.317 | D10: =D9+D8 -> 21213.936 | E10: =E9+E8 -> 29560.874 | G10: =G9+G8 -> 34673.364 | H10: =H9+H8 -> 37882.2 | I10: =I9+I8 -> 41411.92 | J10: =J9+J8 -> 45294.612 | K10: =K9+K8 -> 49565.574
B11: D&A | C11: =SUMIF('P&L assumptions'!$A:$B,'P&L '!$B11, 'P&L assumptions'!C:C) -> -2907.8 | D11: =SUMIF('P&L assumptions'!$A:$B,'P&L '!$B11, 'P&L assumptions'!D:D) -> -4649.8 | E11: =SUMIF('P&L assumptions'!$A:$B,'P&L '!$B11, 'P&L assumptions'!E:E) -> -6430.66 | G11: =SUMIF('P&L assumptions'!$A:$B,'P&L '!$B11, 'P&L assumptions'!G:G) -> -4584.052 | H11: =SUMIF('P&L assumptions'!$A:$B,'P&L '!$B11, 'P&L assumptions'!H:H) -> -5042.4572 | I11: =SUMIF('P&L assumptions'!$A:$B,'P&L '!$B11, 'P&L assumptions'!I:I) -> -5546.7029 | J11: =SUMIF('P&L assumptions'!$A:$B,'P&L '!$B11, 'P&L assumptions'!J:J) -> -6101.3732 | K11: =SUMIF('P&L assumptions'!$A:$B,'P&L '!$B11, 'P&L assumptions'!K:K) -> -6711.5105
B12: EBIT | C12: =C11+C10 -> 17409.517 | D12: =D11+D10 -> 16564.136 | E12: =E11+E10 -> 23130.214 | G12: =G11+G10 -> 30089.312 | H12: =H11+H10 -> 32839.743 | I12: =I11+I10 -> 35865.218 | J12: =J11+J10 -> 39193.239 | K12: =K11+K10 -> 42854.063
B13: Interest expense | C13: =SUMIF('P&L assumptions'!$A:$B,'P&L '!$B13, 'P&L assumptions'!C:C) -> -1266.3 | D13: =SUMIF('P&L assumptions'!$A:$B,'P&L '!$B13, 'P&L assumptions'!D:D) -> -2190.9 | E13: =SUMIF('P&L assumptions'!$A:$B,'P&L '!$B13, 'P&L assumptions'!E:E) -> -2663.92 | G13: =SUMIF('P&L assumptions'!$A:$B,'P&L '!$B13, 'P&L assumptions'!G:G) -> -2663.92 | H13: =SUMIF('P&L assumptions'!$A:$B,'P&L '!$B13, 'P&L assumptions'!H:H) -> -2663.92 | I13: =SUMIF('P&L assumptions'!$A:$B,'P&L '!$B13, 'P&L assumptions'!I:I) -> -2663.92 | J13: =SUMIF('P&L assumptions'!$A:$B,'P&L '!$B13, 'P&L assumptions'!J:J) -> -2663.92 | K13: =SUMIF('P&L assumptions'!$A:$B,'P&L '!$B13, 'P&L assumptions'!K:K) -> -2663.92
B14: Extraordinary income | C14: =SUMIF('P&L assumptions'!$A:$B,'P&L '!$B14, 'P&L assumptions'!C:C) -> -317.58 | D14: =SUMIF('P&L assumptions'!$A:$B,'P&L '!$B14, 'P&L assumptions'!D:D) -> -864.3 | E14: =SUMIF('P&L assumptions'!$A:$B,'P&L '!$B14, 'P&L assumptions'!E:E) -> -320.26 | G14: 0 | H14: 0 | I14: 0 | J14: 0 | K14: 0
B15: EBT | C15: =C14+C13+C12 -> 15825.637 | D15: =D14+D13+D12 -> 13508.936 | E15: =E14+E13+E12 -> 20146.034 | G15: =G14+G13+G12 -> 27425.392 | H15: =H14+H13+H12 -> 30175.823 | I15: =I14+I13+I12 -> 33201.298 | J15: =J14+J13+J12 -> 36529.319 | K15: =K14+K13+K12 -> 40190.143
B16: Tax rate | C16: =C17/C15 -> -0.24048169 | D16: =D17/D15 -> -0.22579069 | E16: =E17/E15 -> -0.18936134 | G16: ='P&L assumptions'!G52 -> -0.18 | H16: ='P&L assumptions'!H52 -> -0.18 | I16: ='P&L assumptions'!I52 -> -0.18 | J16: ='P&L assumptions'!J52 -> -0.18 | K16: ='P&L assumptions'!K52 -> -0.18
B17: Taxes | C17: =SUMIF('P&L assumptions'!$A:$B,'P&L '!$B17, 'P&L assumptions'!C:C) -> -3805.776 | D17: =SUMIF('P&L assumptions'!$A:$B,'P&L '!$B17, 'P&L assumptions'!D:D) -> -3050.192 | E17: =SUMIF('P&L assumptions'!$A:$B,'P&L '!$B17, 'P&L assumptions'!E:E) -> -3814.88 | G17: =G15*G16 -> -4936.5706 | H17: =H15*H16 -> -5431.6482 | I17: =I15*I16 -> -5976.2336 | J17: =J15*J16 -> -6575.2775 | K17: =K15*K16 -> -7234.2258
B18: Net income | C18: =C17+C15 -> 12019.861 | D18: =D17+D15 -> 10458.744 | E18: =E17+E15 -> 16331.154 | G18: =G17+G15 -> 22488.821 | H18: =H17+H15 -> 24744.175 | I18: =I17+I15 -> 27225.064 | J18: =J17+J15 -> 29954.042 | K18: =K17+K15 -> 32955.917

Sheet BS
B1: Balance Sheet
B3: $ in thousands | C3: 31Dec18 Actual | D3: 31Dec19 Actual | E3: 31Dec20 Actual | G3: 31Dec21 Forecast | H3: 31Dec22 Forecast | I3: 31Dec23 Forecast | J3: 31Dec24 Forecast | K3: 31Dec25 Forecast | M3: Note
B4: Intangible assets | C4: ='BS source'!D4 -> 5961.6 | D4: ='BS source'!E4 -> 5840 | E4: ='BS source'!F4 -> 5650 | G4: =$E$4 -> 5650 | H4: =$E$4 -> 5650 | I4: =$E$4 -> 5650 | J4: =$E$4 -> 5650 | K4: =$E$4 -> 5650 | M4: Flat
B5: PP&E | C5: =SUMIF('BS assumptions'!$B:$B,BS!$B5,'BS assumptions'!C:C) -> 45106.4 | D5: =SUMIF('BS assumptions'!$B:$B,BS!$B5,'BS assumptions'!D:D) -> 49072.4 | E5: =SUMIF('BS assumptions'!$B:$B,BS!$B5,'BS assumptions'!E:E) -> 56109.2 | G5: =SUMIF('BS assumptions'!$B:$B,BS!$B5,'BS assumptions'!G:G) -> 59898.019 | H5: =SUMIF('BS assumptions'!$B:$B,BS!$B5,'BS assumptions'!H:H) -> 65887.821 | I5: =SUMIF('BS assumptions'!$B:$B,BS!$B5,'BS assumptions'!I:I) -> 72476.603 | J5: =SUMIF('BS assumptions'!$B:$B,BS!$B5,'BS assumptions'!J:J) -> 79724.263 | K5: =SUMIF('BS assumptions'!$B:$B,BS!$B5,'BS assumptions'!K:K) -> 87696.689
B6: Financial assets | C6: ='BS source'!D6 -> 8824 | D6: ='BS source'!E6 -> 9831 | E6: ='BS source'!F6 -> 10323 | G6: =$E$6 -> 10323 | H6: =$E$6 -> 10323 | I6: =$E$6 -> 10323 | J6: =$E$6 -> 10323 | K6: =$E$6 -> 10323 | M6: Flat
B8: Inventory | C8: =SUMIF('BS assumptions'!$B:$B,BS!$B8,'BS assumptions'!C:C) -> 31167.2 | D8: =SUMIF('BS assumptions'!$B:$B,BS!$B8,'BS assumptions'!D:D) -> 36396.8 | E8: =SUMIF('BS assumptions'!$B:$B,BS!$B8,'BS assumptions'!E:E) -> 46212 | G8: =SUMIF('BS assumptions'!$B:$B,BS!$B8,'BS assumptions'!G:G) -> 51102.671 | H8: =SUMIF('BS assumptions'!$B:$B,BS!$B8,'BS assumptions'!H:H) -> 56212.938 | I8: =SUMIF('BS assumptions'!$B:$B,BS!$B8,'BS assumptions'!I:I) -> 61834.231 | J8: =SUMIF('BS assumptions'!$B:$B,BS!$B8,'BS assumptions'!J:J) -> 68017.654 | K8: =SUMIF('BS assumptions'!$B:$B,BS!$B8,'BS assumptions'!K:K) -> 74819.42
B9: Trade receivable | C9: =SUMIF('BS assumptions'!$B:$B,BS!$B9,'BS assumptions'!C:C) -> 32883.6 | D9: =SUMIF('BS assumptions'!$B:$B,BS!$B9,'BS assumptions'!D:D) -> 38556 | E9: =SUMIF('BS assumptions'!$B:$B,BS!$B9,'BS assumptions'!E:E) -> 43581.6 | G9: =SUMIF('BS assumptions'!$B:$B,BS!$B9,'BS assumptions'!G:G) -> 47352.305 | H9: =SUMIF('BS assumptions'!$B:$B,BS!$B9,'BS assumptions'!H:H) -> 52087.535 | I9: =SUMIF('BS assumptions'!$B:$B,BS!$B9,'BS assumptions'!I:I) -> 57296.289 | J9: =SUMIF('BS assumptions'!$B:$B,BS!$B9,'BS assumptions'!J:J) -> 63025.918 | K9: =SUMIF('BS assumptions'!$B:$B,BS!$B9,'BS assumptions'!K:K) -> 69328.509
B10: Other assets | C10: =SUMIF('BS assumptions'!$B:$B,BS!$B10,'BS assumptions'!C:C) -> 8841.6 | D10: =SUMIF('BS assumptions'!$B:$B,BS!$B10,'BS assumptions'!D:D) -> 11359.2 | E10: =SUMIF('BS assumptions'!$B:$B,BS!$B10,'BS assumptions'!E:E) -> 17602.8 | G10: =SUMIF('BS assumptions'!$B:$B,BS!$B10,'BS assumptions'!G:G) -> 14867.518 | H10: =SUMIF('BS assumptions'!$B:$B,BS!$B10,'BS assumptions'!H:H) -> 16354.27 | I10: =SUMIF('BS assumptions'!$B:$B,BS!$B10,'BS assumptions'!I:I) -> 17989.697 | J10: =SUMIF('BS assumptions'!$B:$B,BS!$B10,'BS assumptions'!J:J) -> 19788.667 | K10: =SUMIF('BS assumptions'!$B:$B,BS!$B10,'BS assumptions'!K:K) -> 21767.534
B12: Cash and equivalents | C12: ='BS source'!D14 -> 11791.2 | D12: ='BS source'!E14 -> 19408.8 | E12: ='BS source'!F14 -> 8173.6 | G12: =E12+'Cash Flow'!G27 -> 24333.994 | H12: =G12+'Cash Flow'!H27 -> 36561.071 | I12: =H12+'Cash Flow'!I27 -> 50017.328 | J12: =I12+'Cash Flow'!J27 -> 64825.681 | K12: =J12+'Cash Flow'!K27 -> 81121.341
B14: Total Assets | C14: =SUM(C4:C12) -> 144575.6 | D14: =SUM(D4:D12) -> 170464.2 | E14: =SUM(E4:E12) -> 187652.2 | G14: =SUM(G4:G12) -> 213527.51 | H14: =SUM(H4:H12) -> 243076.64 | I14: =SUM(I4:I12) -> 275587.15 | J14: =SUM(J4:J12) -> 311355.18 | K14: =SUM(K4:K12) -> 350706.49
B16: Trade payable | C16: =SUMIF('BS assumptions'!$B:$B,BS!$B16,'BS assumptions'!C:C) -> 15891.2 | D16: =SUMIF('BS assumptions'!$B:$B,BS!$B16,'BS assumptions'!D:D) -> 26351.6 | E16: =SUMIF('BS assumptions'!$B:$B,BS!$B16,'BS assumptions'!E:E) -> 36189.6 | G16: =SUMIF('BS assumptions'!$B:$B,BS!$B16,'BS assumptions'!G:G) -> 40019.588 | H16: =SUMIF('BS assumptions'!$B:$B,BS!$B16,'BS assumptions'!H:H) -> 44021.547 | I16: =SUMIF('BS assumptions'!$B:$B,BS!$B16,'BS assumptions'!I:I) -> 48423.702 | J16: =SUMIF('BS assumptions'!$B:$B,BS!$B16,'BS assumptions'!J:J) -> 53266.072 | K16: =SUMIF('BS assumptions'!$B:$B,BS!$B16,'BS assumptions'!K:K) -> 58592.679
B17: Other liabilities | C17: =SUMIF('BS assumptions'!$B:$B,BS!$B17,'BS assumptions'!C:C) -> 5969.0387 | D17: =SUMIF('BS assumptions'!$B:$B,BS!$B17,'BS assumptions'!D:D) -> 5800.356 | E17: =SUMIF('BS assumptions'!$B:$B,BS!$B17,'BS assumptions'!E:E) -> 8473.4464 | G17: =SUMIF('BS assumptions'!$B:$B,BS!$B17,'BS assumptions'!G:G) -> 8029.9438 | H17: =SUMIF('BS assumptions'!$B:$B,BS!$B17,'BS assumptions'!H:H) -> 8832.9382 | I17: =SUMIF('BS assumptions'!$B:$B,BS!$B17,'BS assumptions'!I:I) -> 9716.2321 | J17: =SUMIF('BS assumptions'!$B:$B,BS!$B17,'BS assumptions'!J:J) -> 10687.855 | K17: =SUMIF('BS assumptions'!$B:$B,BS!$B17,'BS assumptions'!K:K) -> 11756.641
B19: Financial liabilities | C19: ='BS source'!J15+'BS source'!J16 -> 41293 | D19: ='BS source'!K15+'BS source'!K16 -> 50645.4 | E19: ='BS source'!L15+'BS source'!L16 -> 51120.8 | G19: =$E$19 -> 51120.8 | H19: =$E$19 -> 51120.8 | I19: =$E$19 -> 51120.8 | J19: =$E$19 -> 51120.8 | K19: =$E$19 -> 51120.8 | M19: Flat
B21: Shareholders' equity | C21: ='BS source'!J8 -> 81422.361 | D21: ='BS source'!K8 -> 87666.844 | E21: ='BS source'!L8 -> 91868.354 | G21: =E21+'P&L '!G18 -> 114357.18 | H21: =G21+'P&L '!H18 -> 139101.35 | I21: =H21+'P&L '!I18 -> 166326.41 | J21: =I21+'P&L '!J18 -> 196280.46 | K21: =J21+'P&L '!K18 -> 229236.37
B23: Total Liabilities & Equities | C23: =SUM(C16:C21) -> 144575.6 | D23: =SUM(D16:D21) -> 170464.2 | E23: =SUM(E16:E21) -> 187652.2 | G23: =SUM(G16:G21) -> 213527.51 | H23: =SUM(H16:H21) -> 243076.64 | I23: =SUM(I16:I21) -> 275587.15 | J23: =SUM(J16:J21) -> 311355.18 | K23: =SUM(K16:K21) -> 350706.49
B25: Check | C25: =C14-C23 -> 0 | D25: =D14-D23 -> 0 | E25: =E14-E23 -> 0 | G25: =G14-G23 -> 0 | H25: =H14-H23 -> 0 | I25: =I14-I23 -> 0 | J25: =J14-J23 -> 0 | K25: =K14-K23 -> 0

Sheet Cash Flow
B1: Cash Flow
B3: $ in thousands | D3: FY19 Actual | E3: FY20 Actual | G3: FY21 Forecast | H3: FY22 Forecast | I3: FY23 Forecast | J3: FY24 Forecast | K3: FY25 Forecast
B4: EBIT | D4: ='P&L '!D12 -> 16564.136 | E4: ='P&L '!E12 -> 23130.214 | F4: ='P&L '!F12 -> 0 | G4: ='P&L '!G12 -> 30089.312 | H4: ='P&L '!H12 -> 32839.743 | I4: ='P&L '!I12 -> 35865.218 | J4: ='P&L '!J12 -> 39193.239 | K4: ='P&L '!K12 -> 42854.063
B5: Operating taxes | D5: =D4*D6 -> -3740.0277 | E5: =E4*E6 -> -4379.9683 | F5: =F4*F6 -> 0 | G5: =G4*G6 -> -5416.0762 | H5: =H4*H6 -> -5911.1538 | I5: =I4*I6 -> -6455.7392 | J5: =J4*J6 -> -7054.7831 | K5: =K4*K6 -> -7713.7314
B6: Operating tax rate | D6: ='P&L '!D16 -> -0.22579069 | E6: ='P&L '!E16 -> -0.18936134 | F6: ='P&L '!F16 -> 0 | G6: ='P&L '!G16 -> -0.18 | H6: ='P&L '!H16 -> -0.18 | I6: ='P&L '!I16 -> -0.18 | J6: ='P&L '!J16 -> -0.18 | K6: ='P&L '!K16 -> -0.18
B7: NOPAT | D7: =SUM(D4:D5) -> 12824.108 | E7: =SUM(E4:E5) -> 18750.245 | G7: =SUM(G4:G5) -> 24673.236 | H7: =SUM(H4:H5) -> 26928.589 | I7: =SUM(I4:I5) -> 29409.478 | J7: =SUM(J4:J5) -> 32138.456 | K7: =SUM(K4:K5) -> 35140.332
B8: Add-back D&A | D8: =-'P&L '!D11 -> 4649.8 | E8: =-'P&L '!E11 -> 6430.66 | F8: =-'P&L '!F11 -> 0 | G8: =-'P&L '!G11 -> 4584.052 | H8: =-'P&L '!H11 -> 5042.4572 | I8: =-'P&L '!I11 -> 5546.7029 | J8: =-'P&L '!J11 -> 6101.3732 | K8: =-'P&L '!K11 -> 6711.5105
B9: Gross Cash Flow | D9: =SUM(D7:D8) -> 17473.908 | E9: =SUM(E7:E8) -> 25180.905 | G9: =SUM(G7:G8) -> 29257.288 | H9: =SUM(H7:H8) -> 31971.047 | I9: =SUM(I7:I8) -> 34956.181 | J9: =SUM(J7:J8) -> 38239.829 | K9: =SUM(K7:K8) -> 41851.842
B10: Inventory | D10: =-BS!D8+BS!C8 -> -5229.6 | E10: =-BS!E8+BS!D8 -> -9815.2 | F10: =-BS!F8+BS!E8 -> 46212 | G10: =-BS!G8+BS!E8 -> -4890.6705 | H10: =-BS!H8+BS!G8 -> -5110.2671 | I10: =-BS!I8+BS!H8 -> -5621.2938 | J10: =-BS!J8+BS!I8 -> -6183.4231 | K10: =-BS!K8+BS!J8 -> -6801.7654
B11: Trade receivables | D11: =-BS!D9+BS!C9 -> -5672.4 | E11: =-BS!E9+BS!D9 -> -5025.6 | F11: =-BS!F9+BS!E9 -> 43581.6 | G11: =-BS!G9+BS!E9 -> -3770.7047 | H11: =-BS!H9+BS!G9 -> -4735.2305 | I11: =-BS!I9+BS!H9 -> -5208.7535 | J11: =-BS!J9+BS!I9 -> -5729.6289 | K11: =-BS!K9+BS!J9 -> -6302.5918
B12: Trade payables | D12: =BS!D16-BS!C16 -> 10460.4 | E12: =BS!E16-BS!D16 -> 9838 | F12: =BS!F16-BS!E16 -> -36189.6 | G12: =BS!G16-BS!E16 -> 3829.9881 | H12: =BS!H16-BS!G16 -> 4001.9588 | I12: =BS!I16-BS!H16 -> 4402.1547 | J12: =BS!J16-BS!I16 -> 4842.3702 | K12: =BS!K16-BS!J16 -> 5326.6072
B14: Investments in working capital | D14: =D10+D11+D12 -> -441.6 | E14: =E10+E11+E12 -> -5002.8 | G14: =G10+G11+G12 -> -4831.3871 | H14: =H10+H11+H12 -> -5843.5387 | I14: =I10+I11+I12 -> -6427.8926 | J14: =J10+J11+J12 -> -7070.6818 | K14: =K10+K11+K12 -> -7777.75
B15: Investments in other assets/liabilities | D15: =-(BS!D10-BS!C10)+(BS!D17-BS!C17) -> -2686.2827 | E15: =-(BS!E10-BS!D10)+(BS!E17-BS!D17) -> -3570.5096 | F15: =-(BS!F10-BS!E10)+(BS!F17-BS!E17) -> 9129.3536 | G15: =-(BS!G10-BS!E10)+(BS!G17-BS!E17) -> 2291.7789 | H15: =-(BS!H10-BS!G10)+(BS!H17-BS!G17) -> -683.75746 | I15: =-(BS!I10-BS!H10)+(BS!I17-BS!H17) -> -752.13321 | J15: =-(BS!J10-BS!I10)+(BS!J17-BS!I17) -> -827.34653 | K15: =-(BS!K10-BS!J10)+(BS!K17-BS!J17) -> -910.08118
B17: Capex | D17: =-(BS!D5-BS!C5)+'P&L '!D11 -> -8615.8 | E17: =-(BS!E5-BS!D5)+'P&L '!E11 -> -13467.46 | F17: =-(BS!F5-BS!E5)+'P&L '!F11 -> 56109.2 | G17: =-(BS!G5-BS!E5)+'P&L '!G11 -> -8372.8708 | H17: =-(BS!H5-BS!G5)+'P&L '!H11 -> -11032.259 | I17: =-(BS!I5-BS!H5)+'P&L '!I11 -> -12135.485 | J17: =-(BS!J5-BS!I5)+'P&L '!J11 -> -13349.033 | K17: =-(BS!K5-BS!J5)+'P&L '!K11 -> -14683.937
B19: Other investments | D19: =-(BS!D4-BS!C4)-(BS!D6-BS!C6) -> -885.4 | E19: =-(BS!E4-BS!D4)-(BS!E6-BS!D6) -> -302 | F19: =-(BS!F4-BS!E4)-(BS!F6-BS!E6) -> 15973 | G19: =-(BS!G4-BS!E4)-(BS!G6-BS!E6) -> 0 | H19: =-(BS!H4-BS!G4)-(BS!H6-BS!G6) -> 0 | I19: =-(BS!I4-BS!H4)-(BS!I6-BS!H6) -> 0 | J19: =-(BS!J4-BS!I4)-(BS!J6-BS!I6) -> 0 | K19: =-(BS!K4-BS!J4)-(BS!K6-BS!J6) -> 0
B21: Extraordinary items | D21: ='P&L '!D14 -> -864.3 | E21: ='P&L '!E14 -> -320.26 | F21: ='P&L '!F14 -> 0 | G21: ='P&L '!G14 -> 0 | H21: ='P&L '!H14 -> 0 | I21: ='P&L '!I14 -> 0 | J21: ='P&L '!J14 -> 0 | K21: ='P&L '!K14 -> 0
B22: UFCF | D22: =SUM(D9,D14,D15,D17,D19,D21) -> 3980.5256 | E22: =SUM(E9,E14,E15,E17,E19,E21) -> 2517.8757 | G22: =SUM(G9,G14,G15,G17,G19,G21) -> 18344.809 | H22: =SUM(H9,H14,H15,H17,H19,H21) -> 14411.491 | I22: =SUM(I9,I14,I15,I17,I19,I21) -> 15640.671 | J22: =SUM(J9,J14,J15,J17,J19,J21) -> 16992.768 | K22: =SUM(K9,K14,K15,K17,K19,K21) -> 18480.074
B23: Interest expenses | D23: ='P&L '!D13 -> -2190.9 | E23: ='P&L '!E13 -> -2663.92 | F23: ='P&L '!F13 -> 0 | G23: ='P&L '!G13 -> -2663.92 | H23: ='P&L '!H13 -> -2663.92 | I23: ='P&L '!I13 -> -2663.92 | J23: ='P&L '!J13 -> -2663.92 | K23: ='P&L '!K13 -> -2663.92
B24: Delta Taxes vs. Operating taxes | D24: ='P&L '!D17-'Cash Flow'!D5 -> 689.83572 | E24: ='P&L '!E17-'Cash Flow'!E5 -> 565.08834 | F24: ='P&L '!F17-'Cash Flow'!F5 -> 0 | G24: ='P&L '!G17-'Cash Flow'!G5 -> 479.5056 | H24: ='P&L '!H17-'Cash Flow'!H5 -> 479.5056 | I24: ='P&L '!I17-'Cash Flow'!I5 -> 479.5056 | J24: ='P&L '!J17-'Cash Flow'!J5 -> 479.5056 | K24: ='P&L '!K17-'Cash Flow'!K5 -> 479.5056
B25: Delta Financial liabilities | D25: =BS!D19-BS!C19 -> 9352.4 | E25: =BS!E19-BS!D19 -> 475.4 | F25: =BS!F19-BS!E19 -> -51120.8
B26: Delta Equity (incl. dividends) | D26: =BS!D21-BS!C21-'P&L '!D18 -> -4214.2613 | E26: =BS!E21-BS!D21-'P&L '!E18 -> -12129.644
B27: Net Cash Flow | D27: =D22+D23+D24+D25+D26 -> 7617.6 | E27: =E24+E23+E25+E26+E22 -> -11235.2 | G27: =G22+G23+G24+G25+G26 -> 16160.394 | H27: =H22+H23+H24+H25+H26 -> 12227.077 | I27: =I22+I23+I24+I25+I26 -> 13456.256 | J27: =J22+J23+J24+J25+J26 -> 14808.353 | K27: =K22+K23+K24+K25+K26 -> 16295.66
B29: Opening cash | D29: =BS!C12 -> 11791.2 | E29: =BS!D12 -> 19408.8 | G29: =BS!E12 -> 8173.6 | H29: =BS!G12 -> 24333.994 | I29: =BS!H12 -> 36561.071 | J29: =BS!I12 -> 50017.328 | K29: =BS!J12 -> 64825.681
B30: Closing cash | D30: =D29+D27 -> 19408.8 | E30: =E29+E27 -> 8173.6 | G30: =G29+G27 -> 24333.994 | H30: =H29+H27 -> 36561.071 | I30: =I29+I27 -> 50017.328 | J30: =J29+J27 -> 64825.681 | K30: =K29+K27 -> 81121.341
B32: Check | D32: =BS!D12-'Cash Flow'!D30 -> -5.4569682e-11 | E32: =BS!E12-'Cash Flow'!E30 -> -1.0913936e-11 | G32: =BS!G12-'Cash Flow'!G30 -> 0 | H32: =BS!H12-'Cash Flow'!H30 -> 0 | I32: =BS!I12-'Cash Flow'!I30 -> 0 | J32: =BS!J12-'Cash Flow'!J30 -> 0 | K32: =BS!K12-'Cash Flow'!K30 -> 0

Sheet DCF Valuation 
B1: DCF Valuation
B4: WACC | C4: 0.1
B5: g | C5: 0.02
G6: 1 | H6: 2 | I6: 3 | J6: 4 | K6: 5
B7: $ in thousands | C7: FY18 Actual | D7: FY19 Actual | E7: FY20 Actual | G7: FY21 Forecast | H7: FY22 Forecast | I7: FY23 Forecast | J7: FY24 Forecast | K7: FY25 Forecast
B8: UFCF | D8: ='Cash Flow'!D22 -> 3980.5256 | E8: ='Cash Flow'!E22 -> 2517.8757 | F8: ='Cash Flow'!F22 -> 0 | G8: ='Cash Flow'!G22 -> 18344.809 | H8: ='Cash Flow'!H22 -> 14411.491 | I8: ='Cash Flow'!I22 -> 15640.671 | J8: ='Cash Flow'!J22 -> 16992.768 | K8: ='Cash Flow'!K22 -> 18480.074
B10: Discount factor | G10: =1/(1+$C$4)^G6 -> 0.90909091 | H10: =1/(1+$C$4)^H6 -> 0.82644628 | I10: =1/(1+$C$4)^I6 -> 0.7513148 | J10: =1/(1+$C$4)^J6 -> 0.68301346 | K10: =1/(1+$C$4)^K6 -> 0.62092132
B11: Present value of UFCF | G11: =G8*G10 -> 16677.099 | H11: =H8*H10 -> 11910.323 | I11: =I8*I10 -> 11751.067 | J11: =J8*J10 -> 11606.289 | K11: =K8*K10 -> 11474.672
B14: DCF Valuation
B15: PV of Cash flows | E15: =SUM(G11:K11) -> 63419.451
B16: Continuing value | E16: =K8*(1+C5)/(C4-C5) -> 235620.95
B17: PV of Continuing value | E17: =E16*K10 -> 146302.07
B18: Enterprise value | E18: =E15+E17 -> 209721.52
B19: () Financial liabilities | E19: =-BS!E19 -> -51120.8
B20: Cash | E20: =BS!E12 -> 8173.6
B21: Equity value | E21: =E18+E19+E20 -> 166774.32 | G21: =C18 -> 0 | H21: 0.09 | I21: 0.1 | J21: 0.11 | K21: 0.12
G22: 0.01
G23: 0.02
G24: 0.03
G25: 0.04
